Workbook

Sheet Slideworks guide
B2: How to use this Excel model:
B3: Use this Excel to compare different solution options. Adjust assumptions under each option and compare return on investment calculations.
B5: Five ways to calculate when a project is a good business case:
B6: Method | C6: Answers the question… | D6: Expressed in… | E6: Typically used for…
B7: Breakeven analysis | C7: How many sales are needed to recoup the investment? | D7: Units sold | E7: Market-focused projects like product development and new market expansion
B8: Return on investment (ROI) | C8: How much profit can we earn? | D8: Percentage | E8: Projects with significant upfront costs, like facilities projects, and productivity projects that accumulate benefits over time
B9: Payback period | C9: How long will it take to recoup the investment? | D9: Months or years | E9: Projects with significant upfront costs, like facilities projects, and productivity projects that accumulate benefits over time
B10: Net present value (NPV) | C10: How much is this project worth to the business? | D10: Dollars/Euro etc. | E10: Projects with large expenditures
B11: Internal rate of return (IRR) | C11: What rate of return will this project deliver over its lifecycle? | D11: Percentage | E11: Projects that a company expects to extend indefinitely, especially those requiring borrowing.
B13: Formatting:
B15: Light yellow cells are input fields
B16: All other cells are calculated

Sheet Project overview
B2: Project description
B4: Insert a brief description of the project
B15: Project details
B17: Project name: | C17: [Insert name of project]
B18: Project category: | C18: [Insert category, if relevant]
B19: Business unit/team: | C19: [Insert business unit/team, if relevant]
B20: Model version: | C20: 1
B21: Date: | C21: [Insert date]
B22: Model prepared by: | C22: [Insert name and title]
B23: Project leader: | C23: [Insert name and title]
B24: Project sponsor: | C24: [Insert name and title]

Sheet Options comparison
B2: Business case options comparison
B3: Overview of investment case for each option
C5: Investment | D5: Net present value (NPV) | E5: Internal rate of return (IRR) | F5: Discounted payback period (years) | G5: Return on investment (ROI) | H5: Description
B6: ='Option 1'!C$4 -> [Insert name of option e.g., Do minimum] | C6: =-SUM('Option 1'!C$101:H$101) -> 162000 | D6: ='Option 1'!C$148 -> 1218882 | E6: ='Option 1'!C$150 -> 0.63730727 | F6: ='Option 1'!C$152 -> 4.32 years | G6: ='Option 1'!C$154 -> 6.5239628 | H6: ='Option 1'!C$5 -> [Insert brief description of scenario]
B7: ='Option 2'!C$4 -> [Insert name of option e.g., Focus on new revenue] | C7: =-SUM('Option 2'!C$101:H$101) -> 162000 | D7: ='Option 2'!C$148 -> 1131482.8 | E7: ='Option 2'!C$150 -> 0.59458994 | F7: ='Option 2'!C$152 -> 5.99 years | G7: ='Option 2'!C$154 -> 5.9844616 | H7: ='Option 1'!C$5 -> [Insert brief description of scenario]
B8: ='Option 3'!C$4 -> [Insert name of option e.g., High growth] | C8: =-SUM('Option 3'!C$101:H$101) -> 306000 | D8: ='Option 3'!C$148 -> 1573574.1 | E8: ='Option 3'!C$150 -> 0.50706001 | F8: ='Option 3'!C$152 -> 5.93 years | G8: ='Option 3'!C$154 -> 4.1423992 | H8: ='Option 1'!C$5 -> [Insert brief description of scenario]
B23: Revenue and cost savings | C23: ='Option 1'!C37 -> Entry | D23: ='Option 1'!D37 -> Year 1 | E23: ='Option 1'!E37 -> Year 2 | F23: ='Option 1'!F37 -> Year 3 | G23: ='Option 1'!G37 -> Year 4 | H23: ='Option 1'!H37 -> Year 5 | I23: ='Option 1'!I37 -> Exit
B24: =B6 -> [Insert name of option e.g., Do minimum] | C24: ='Option 1'!C$44+'Option 1'!C$49 -> 0 | D24: ='Option 1'!D$44+'Option 1'!D$49 -> 145000 | E24: ='Option 1'!E$44+'Option 1'!E$49 -> 134000 | F24: ='Option 1'!F$44+'Option 1'!F$49 -> 152000 | G24: ='Option 1'!G$44+'Option 1'!G$49 -> 188000 | H24: ='Option 1'!H$44+'Option 1'!H$49 -> 230000
B25: =B7 -> [Insert name of option e.g., Focus on new revenue] | C25: ='Option 2'!C$44+'Option 2'!C$49 -> 0 | D25: ='Option 2'!D$44+'Option 2'!D$49 -> 95000 | E25: ='Option 2'!E$44+'Option 2'!E$49 -> 104000 | F25: ='Option 2'!F$44+'Option 2'!F$49 -> 122000 | G25: ='Option 2'!G$44+'Option 2'!G$49 -> 158000 | H25: ='Option 2'!H$44+'Option 2'!H$49 -> 200000
B26: =B8 -> [Insert name of option e.g., High growth] | C26: ='Option 3'!C$44+'Option 3'!C$49 -> 0 | D26: ='Option 3'!D$44+'Option 3'!D$49 -> 265000 | E26: ='Option 3'!E$44+'Option 3'!E$49 -> 254000 | F26: ='Option 3'!F$44+'Option 3'!F$49 -> 290000 | G26: ='Option 3'!G$44+'Option 3'!G$49 -> 368000 | H26: ='Option 3'!H$44+'Option 3'!H$49 -> 410000
B28: EBITDA | C28: =C23 -> Entry | D28: =D23 -> Year 1 | E28: =E23 -> Year 2 | F28: =F23 -> Year 3 | G28: =G23 -> Year 4 | H28: =H23 -> Year 5 | I28: =I23 -> Exit
B29: =B6 -> [Insert name of option e.g., Do minimum] | C29: ='Option 1'!C$72 -> 0 | D29: ='Option 1'!D$72 -> 95000 | E29: ='Option 1'!E$72 -> 84000 | F29: ='Option 1'!F$72 -> 102000 | G29: ='Option 1'!G$72 -> 138000 | H29: ='Option 1'!H$72 -> 180000
B30: =B7 -> [Insert name of option e.g., Focus on new revenue] | C30: ='Option 2'!C$72 -> 0 | D30: ='Option 2'!D$72 -> 69000 | E30: ='Option 2'!E$72 -> 78000 | F30: ='Option 2'!F$72 -> 96000 | G30: ='Option 2'!G$72 -> 132000 | H30: ='Option 2'!H$72 -> 174000
B31: =B8 -> [Insert name of option e.g., High growth] | C31: ='Option 3'!C$72 -> 0 | D31: ='Option 3'!D$72 -> 125000 | E31: ='Option 3'!E$72 -> 114000 | F31: ='Option 3'!F$72 -> 150000 | G31: ='Option 3'!G$72 -> 228000 | H31: ='Option 3'!H$72 -> 270000
B33: Total cash flows | C33: =C23 -> Entry | D33: =D23 -> Year 1 | E33: =E23 -> Year 2 | F33: =F23 -> Year 3 | G33: =G23 -> Year 4 | H33: =H23 -> Year 5 | I33: =I23 -> Exit
B34: =B6 -> [Insert name of option e.g., Do minimum] | C34: ='Option 1'!C$115 -> -162000 | D34: ='Option 1'!D$115 -> 25477.315 | E34: ='Option 1'!E$115 -> 24788.663 | F34: ='Option 1'!F$115 -> 39604.966 | G34: ='Option 1'!G$115 -> 67063.208 | H34: ='Option 1'!H$115 -> 101137.17 | I34: ='Option 1'!I$115 -> 2123880.5
B35: =B7 -> [Insert name of option e.g., Focus on new revenue] | C35: ='Option 2'!C$115 -> -162000 | D35: ='Option 2'!D$115 -> 5197.3151 | E35: ='Option 2'!E$115 -> 20108.663 | F35: ='Option 2'!F$115 -> 34924.966 | G35: ='Option 2'!G$115 -> 62383.208 | H35: ='Option 2'!H$115 -> 96457.168 | I35: ='Option 2'!I$115 -> 2025600.5
B36: =B8 -> [Insert name of option e.g., High growth] | C36: ='Option 3'!C$115 -> -306000 | D36: ='Option 3'!D$115 -> -7055.1781 | E36: ='Option 3'!E$115 -> 13254.263 | F36: ='Option 3'!F$115 -> 41211.572 | G36: ='Option 3'!G$115 -> 99605.907 | H36: ='Option 3'!H$115 -> 142369.29 | I36: ='Option 3'!I$115 -> 2989755.1

Sheet Option 1
B2: Option 1: | C2: [Insert name of option e.g., Do minimum]
B4: Option 1: | C4: =C2 -> [Insert name of option e.g., Do minimum]
B5: Description: | C5: [Insert brief description of scenario]
B7: Assumptions | C7: Entry | D7: Year 1 | E7: Year 2 | F7: Year 3 | G7: Year 4 | H7: Year 5 | I7: Exit
B9: Business Case Timing
B10: Start Date | C10: 45778
B11: Fiscal Year Date | C11: 45838
B12: Date | C12: =C10 -> 45778 | D12: =DATE(YEAR($C$11)+D13,6,30) -> 46203 | E12: =DATE(YEAR($C$11)+E13,6,30) -> 46568 | F12: =DATE(YEAR($C$11)+F13,6,30) -> 46934 | G12: =DATE(YEAR($C$11)+G13,6,30) -> 47299 | H12: =DATE(YEAR($C$11)+H13,6,30) -> 47664 | I12: =DATE(YEAR($C$11)+I13,6,30) -> 48029
B13: Time periods | C13: 0 | D13: 1 | E13: =D13+1 -> 2 | F13: =E13+1 -> 3 | G13: =F13+1 -> 4 | H13: =G13+1 -> 5 | I13: =H13+1 -> 6
B14: Year fraction | D14: =YEARFRAC(C12,D12) -> 1.1638889 | E14: =YEARFRAC(D12,E12) -> 1 | F14: =YEARFRAC(E12,F12) -> 1 | G14: =YEARFRAC(F12,G12) -> 1 | H14: =YEARFRAC(G12,H12) -> 1
B16: Operations
B17: Cost of goods sold (% of revenue) | C17: 0.4
B18: Tax rate | C18: 0.22
B19: Depreciation & amortization | C19: 0.1
B21: Project investment
B22: Buffer on capex investments | C22: 0.2
B24: Working capital
B25: Accounts receivable (days) | C25: 30
B26: Inventory (days) | C26: 60
B27: Accounts payable (days) | C27: 30
B29: Financing
B30: Interest rate on debt (%) | C30: 0.1
B31: Yearly debt repayments (% of total debt) | C31: 0.2
B33: DCF Analysis
B34: Discount Rate | C34: 0.1
B35: Perpetual Growth Rate | C35: 0.05
B37: Business case | C37: Entry | D37: Year 1 | E37: Year 2 | F37: Year 3 | G37: Year 4 | H37: Year 5 | I37: Exit
B39: Operations
B41: Revenues
B42: New revenue generated | D42: 75000 | E42: 90000 | F42: 120000 | G42: 180000 | H42: 250000
B43: Cost of goods sold (COGS) | D43: =D42*$C$17 -> 30000 | E43: =E42*$C$17 -> 36000 | F43: =F42*$C$17 -> 48000 | G43: =G42*$C$17 -> 72000 | H43: =H42*$C$17 -> 100000
B44: Gross margin | C44: =(C42-C43) -> 0 | D44: =(D42-D43) -> 45000 | E44: =(E42-E43) -> 54000 | F44: =(F42-F43) -> 72000 | G44: =(G42-G43) -> 108000 | H44: =(H42-H43) -> 150000
B46: Cost savings
B47: Cost savings #1 | D47: 100000 | E47: 80000 | F47: 80000 | G47: 80000 | H47: 80000
B48: Cost savings #1 | D48: 0 | E48: 0 | F48: 0 | G48: 0 | H48: 0
B49: Total cost savings | C49: =SUM(C47:C48) -> 0 | D49: =SUM(D47:D48) -> 100000 | E49: =SUM(E47:E48) -> 80000 | F49: =SUM(F47:F48) -> 80000 | G49: =SUM(G47:G48) -> 80000 | H49: =SUM(H47:H48) -> 80000
B51: Ongoing project costs
B53: Operating expenses
B54: Ongoing cost #1 (e.g., salaries) | D54: 30000 | E54: =D54 -> 30000 | F54: =E54 -> 30000 | G54: =F54 -> 30000 | H54: =G54 -> 30000
B55: Ongoing cost #2 (e.g., personnel expenses) | D55: 15000 | E55: =D55 -> 15000 | F55: =E55 -> 15000 | G55: =F55 -> 15000 | H55: =G55 -> 15000
...

Sheet Option 2
B2: Option 2: | C2: [Insert name of option e.g., Focus on new revenue]
B4: Option 2: | C4: =C2 -> [Insert name of option e.g., Focus on new revenue]
B5: Description: | C5: [Insert brief description of scenario]
B7: Assumptions | C7: Entry | D7: Year 1 | E7: Year 2 | F7: Year 3 | G7: Year 4 | H7: Year 5 | I7: Exit
B9: Business Case Timing
B10: Start Date | C10: 45778
B11: Fiscal Year Date | C11: 45838
B12: Date | C12: =C10 -> 45778 | D12: =DATE(YEAR($C$11)+D13,6,30) -> 46203 | E12: =DATE(YEAR($C$11)+E13,6,30) -> 46568 | F12: =DATE(YEAR($C$11)+F13,6,30) -> 46934 | G12: =DATE(YEAR($C$11)+G13,6,30) -> 47299 | H12: =DATE(YEAR($C$11)+H13,6,30) -> 47664 | I12: =DATE(YEAR($C$11)+I13,6,30) -> 48029
B13: Time periods | C13: 0 | D13: 1 | E13: =D13+1 -> 2 | F13: =E13+1 -> 3 | G13: =F13+1 -> 4 | H13: =G13+1 -> 5 | I13: =H13+1 -> 6
B14: Year fraction | D14: =YEARFRAC(C12,D12) -> 1.1638889 | E14: =YEARFRAC(D12,E12) -> 1 | F14: =YEARFRAC(E12,F12) -> 1 | G14: =YEARFRAC(F12,G12) -> 1 | H14: =YEARFRAC(G12,H12) -> 1
B16: Operations
B17: Cost of goods sold (% of revenue) | C17: 0.4
B18: Tax rate | C18: 0.22
B19: Depreciation & amortization | C19: 0.1
B21: Project investment
B22: Buffer on capex investments | C22: 0.2
B24: Working capital
B25: Accounts receivable (days) | C25: 30
B26: Inventory (days) | C26: 60
B27: Accounts payable (days) | C27: 30
B29: Financing
B30: Interest rate on debt (%) | C30: 0.1
B31: Yearly debt repayments (% of total debt) | C31: 0.2
B33: DCF Analysis
B34: Discount Rate | C34: 0.1
B35: Perpetual Growth Rate | C35: 0.05
B37: Business case | C37: Entry | D37: Year 1 | E37: Year 2 | F37: Year 3 | G37: Year 4 | H37: Year 5 | I37: Exit
B39: Operations
B41: Revenues
B42: New revenue generated | D42: 75000 | E42: 90000 | F42: 120000 | G42: 180000 | H42: 250000
B43: Cost of goods sold (COGS) | D43: =D42*$C$17 -> 30000 | E43: =E42*$C$17 -> 36000 | F43: =F42*$C$17 -> 48000 | G43: =G42*$C$17 -> 72000 | H43: =H42*$C$17 -> 100000
B44: Gross margin | C44: =(C42-C43) -> 0 | D44: =(D42-D43) -> 45000 | E44: =(E42-E43) -> 54000 | F44: =(F42-F43) -> 72000 | G44: =(G42-G43) -> 108000 | H44: =(H42-H43) -> 150000
B46: Cost savings
B47: Cost savings #1 | D47: 50000 | E47: 50000 | F47: 50000 | G47: 50000 | H47: 50000
B48: Cost savings #1 | D48: 0 | E48: 0 | F48: 0 | G48: 0 | H48: 0
B49: Total cost savings | C49: =SUM(C47:C48) -> 0 | D49: =SUM(D47:D48) -> 50000 | E49: =SUM(E47:E48) -> 50000 | F49: =SUM(F47:F48) -> 50000 | G49: =SUM(G47:G48) -> 50000 | H49: =SUM(H47:H48) -> 50000
B51: Ongoing project costs
B53: Operating expenses
B54: Ongoing cost #1 (e.g., salaries) | D54: 20000 | E54: =D54 -> 20000 | F54: =E54 -> 20000 | G54: =F54 -> 20000 | H54: =G54 -> 20000
B55: Ongoing cost #2 (e.g., personnel expenses) | D55: 5000 | E55: =D55 -> 5000 | F55: =E55 -> 5000 | G55: =F55 -> 5000 | H55: =G55 -> 5000
...

Sheet Option 3
B2: Option 3: | C2: [Insert name of option e.g., High growth]
B4: Option 3: | C4: =C2 -> [Insert name of option e.g., High growth]
B5: Description: | C5: [Insert brief description of scenario]
B7: Assumptions | C7: Entry | D7: Year 1 | E7: Year 2 | F7: Year 3 | G7: Year 4 | H7: Year 5 | I7: Exit
B9: Business Case Timing
B10: Start Date | C10: 45778
B11: Fiscal Year Date | C11: 45838
B12: Date | C12: =C10 -> 45778 | D12: =DATE(YEAR($C$11)+D13,6,30) -> 46203 | E12: =DATE(YEAR($C$11)+E13,6,30) -> 46568 | F12: =DATE(YEAR($C$11)+F13,6,30) -> 46934 | G12: =DATE(YEAR($C$11)+G13,6,30) -> 47299 | H12: =DATE(YEAR($C$11)+H13,6,30) -> 47664 | I12: =DATE(YEAR($C$11)+I13,6,30) -> 48029
B13: Time periods | C13: 0 | D13: 1 | E13: =D13+1 -> 2 | F13: =E13+1 -> 3 | G13: =F13+1 -> 4 | H13: =G13+1 -> 5 | I13: =H13+1 -> 6
B14: Year fraction | D14: =YEARFRAC(C12,D12) -> 1.1638889 | E14: =YEARFRAC(D12,E12) -> 1 | F14: =YEARFRAC(E12,F12) -> 1 | G14: =YEARFRAC(F12,G12) -> 1 | H14: =YEARFRAC(G12,H12) -> 1
B16: Operations
B17: Cost of goods sold (% of revenue) | C17: 0.4
B18: Tax rate | C18: 0.22
B19: Depreciation & amortization | C19: 0.1
B21: Project investment
B22: Buffer on capex investments | C22: 0.2
B24: Working capital
B25: Accounts receivable (days) | C25: 30
B26: Inventory (days) | C26: 60
B27: Accounts payable (days) | C27: 30
B29: Financing
B30: Interest rate on debt (%) | C30: 0.1
B31: Yearly debt repayments (% of total debt) | C31: 0.2
B33: DCF Analysis
B34: Discount Rate | C34: 0.1
B35: Perpetual Growth Rate | C35: 0.05
B37: Business case | C37: Entry | D37: Year 1 | E37: Year 2 | F37: Year 3 | G37: Year 4 | H37: Year 5 | I37: Exit
B39: Operations
B41: Revenues
B42: New revenue generated | D42: 275000 | E42: 290000 | F42: 350000 | G42: 480000 | H42: 550000
B43: Cost of goods sold (COGS) | D43: =D42*$C$17 -> 110000 | E43: =E42*$C$17 -> 116000 | F43: =F42*$C$17 -> 140000 | G43: =G42*$C$17 -> 192000 | H43: =H42*$C$17 -> 220000
B44: Gross margin | C44: =(C42-C43) -> 0 | D44: =(D42-D43) -> 165000 | E44: =(E42-E43) -> 174000 | F44: =(F42-F43) -> 210000 | G44: =(G42-G43) -> 288000 | H44: =(H42-H43) -> 330000
B46: Cost savings
B47: Cost savings #1 | D47: 100000 | E47: 80000 | F47: 80000 | G47: 80000 | H47: 80000
B48: Cost savings #1 | D48: 0 | E48: 0 | F48: 0 | G48: 0 | H48: 0
B49: Total cost savings | C49: =SUM(C47:C48) -> 0 | D49: =SUM(D47:D48) -> 100000 | E49: =SUM(E47:E48) -> 80000 | F49: =SUM(F47:F48) -> 80000 | G49: =SUM(G47:G48) -> 80000 | H49: =SUM(H47:H48) -> 80000
B51: Ongoing project costs
B53: Operating expenses
B54: Ongoing cost #1 (e.g., salaries) | D54: 100000 | E54: =D54 -> 100000 | F54: =E54 -> 100000 | G54: =F54 -> 100000 | H54: =G54 -> 100000
B55: Ongoing cost #2 (e.g., personnel expenses) | D55: 25000 | E55: =D55 -> 25000 | F55: =E55 -> 25000 | G55: =F55 -> 25000 | H55: =G55 -> 25000
...
